Workbook

Sheet Dashboard
A1: INVENTÁRIO – UFV NORONHA VERDE | DASHBOARD & CURVA ABC
A3: Posição de estoque em 27/09/2026 • fonte: abas originais do inventário • valores em R$
A5: VALOR TOTAL EM ESTOQUE | E5: PRODUTOS DISTINTOS | I5: LOCAIS DE ESTOQUE | M5: ITENS CLASSE A | Q5: % DO VALOR EM CLASSE A | U5: MAIOR ITEM (% DO TOTAL)
A6: ='Curva ABC'!G2849 -> 15238739 | E6: =COUNT('Curva ABC'!$B$8:$B$2847) -> 2840 | I6: =COUNTA(Análises!A11:A15) -> 5 | M6: =Análises!B4 -> 255 | Q6: =Análises!E4 -> 0.79982061 | U6: ='Curva ABC'!H8 -> 0.045271325
A9: Resumo por classe ABC
A10: Classe | C10: Nº itens | E10: % itens | G10: Valor (R$) | J10: % valor | M10: Como ler: poucos itens (A) concentram a maior parte do valor; priorize contagem, segurança e reposição neles.
A11: =Análises!A4 -> A | C11: =Análises!B4 -> 255 | E11: =Análises!C4 -> 0.089788732 | G11: =Análises!D4 -> 12188258 | J11: =Análises!E4 -> 0.79982061
A12: =Análises!A5 -> B | C12: =Análises!B5 -> 609 | E12: =Análises!C5 -> 0.21443662 | G12: =Análises!D5 -> 2288357.1 | J12: =Análises!E5 -> 0.15016709
A13: =Análises!A6 -> C | C13: =Análises!B6 -> 1976 | E13: =Análises!C6 -> 0.69577465 | G13: =Análises!D6 -> 762124.34 | J13: =Análises!E6 -> 0.050012296
A14: =Análises!A7 -> Total | C14: =Análises!B7 -> 2840 | E14: =Análises!C7 -> 1 | G14: =Análises!D7 -> 15238739 | J14: =Análises!E7 -> 1

Sheet Curva ABC
A1: CURVA ABC DE ESTOQUE – CONSOLIDADA POR PRODUTO
A2: Valor = soma do saldo financeiro do produto em todos os locais (aba Base). Ordem por valor decrescente (ordenada em 27/09/2026).
A4: Limite classe A (% acumulado do valor) | E4: 0.8 | G4: ← células amarelas: edite para mudar o corte (A: acumulado ≤ limite A; B: ≤ limite B; C: restante)
A5: Limite classe B (% acumulado do valor) | E5: 0.95
A7: Rank | B7: IDPRD | C7: Código | D7: Descrição | E7: Natureza | F7: Nº locais | G7: Valor em estoque (R$) | H7: % do valor | I7: % acumulado | J7: % acum. itens | K7: Classe
A8: 1 | B8: 1322479 | C8: 17.01.1200 | D8: CABO UNIPOLAR DE ALUMÍNIO, CLASSE 0,6/1KV, ISOL XLPE SEÇÃO 400MM² RES A CHAMA, UVB, SEM CHUMBO - REF PRYSMYAN OU SIMILAR | E8: 3.7.1.018 - Serviço de instalações elétricas/telefônica/lógica | F8: =COUNTIF(Base!$D$2:$D$2878,B8) -> 1 | G8: =SUMIF(Base!$D$2:$D$2878,B8,Base!$I$2:$I$2878) -> 689877.92 | H8: =IF($G$2849=0,0,G8/$G$2849) -> 0.045271325 | I8: =H8 -> 0.045271325 | J8: =A8/2840 -> 0.00035211268 | K8: =IF(I8<=$E$4,"A",IF(I8<=$E$5,"B","C")) -> A
A9: 2 | B9: 1258883 | C9: 32.13.0045 | D9: CARPA DORMITÓRIO COM DIVISÓRIA EM PVC - 8 X 16M | E9: 6.1.2.001 - Equipamentos | F9: =COUNTIF(Base!$D$2:$D$2878,B9) -> 1 | G9: =SUMIF(Base!$D$2:$D$2878,B9,Base!$I$2:$I$2878) -> 595000 | H9: =IF($G$2849=0,0,G9/$G$2849) -> 0.039045225 | I9: =I8+H9 -> 0.08431655 | J9: =A9/2840 -> 0.00070422535 | K9: =IF(I9<=$E$4,"A",IF(I9<=$E$5,"B","C")) -> A
A10: 3 | B10: 1328273 | C10: 17.01.1206 | D10: CABO BT 6MM² SOLAR, CONDUTOR DE COBRE FLEXÍVEL ESTANHADO, CAPA NA COR PRETA COM PROTEÇÃO UV | E10: 3.8.1.017 - Instalações elétricas/telefônicas/lógica | F10: =COUNTIF(Base!$D$2:$D$2878,B10) -> 1 | G10: =SUMIF(Base!$D$2:$D$2878,B10,Base!$I$2:$I$2878) -> 355560.3 | H10: =IF($G$2849=0,0,G10/$G$2849) -> 0.023332658 | I10: =I9+H10 -> 0.10764921 | J10: =A10/2840 -> 0.001056338 | K10: =IF(I10<=$E$4,"A",IF(I10<=$E$5,"B","C")) -> A
A11: 4 | B11: 387747 | C11: 17.01.0846 | D11: CABO DE COBRE NU 50MM²,TÊMPERA MEIO DURA,7 FIOS E ENCORDOAMENTO CLASSE 2A | E11: 3.8.1.017 - Instalações elétricas/telefônicas/lógica | F11: =COUNTIF(Base!$D$2:$D$2878,B11) -> 1 | G11: =SUMIF(Base!$D$2:$D$2878,B11,Base!$I$2:$I$2878) -> 348968.62 | H11: =IF($G$2849=0,0,G11/$G$2849) -> 0.022900098 | I11: =I10+H11 -> 0.13054931 | J11: =A11/2840 -> 0.0014084507 | K11: =IF(I11<=$E$4,"A",IF(I11<=$E$5,"B","C")) -> A
A12: 5 | B12: 1328095 | C12: 17.01.1203 | D12: CABO DE COBRE MONOPOLAR 240 MM², CLASSE 2, 8,7/15 KV, ISOLAÇÃO EPR, COBERTURA PVC PRETO, BLINDAGEM 25 MM² | E12: 3.8.1.017 - Instalações elétricas/telefônicas/lógica | F12: =COUNTIF(Base!$D$2:$D$2878,B12) -> 1 | G12: =SUMIF(Base!$D$2:$D$2878,B12,Base!$I$2:$I$2878) -> 340633.99 | H12: =IF($G$2849=0,0,G12/$G$2849) -> 0.022353161 | I12: =I11+H12 -> 0.15290247 | J12: =A12/2840 -> 0.0017605634 | K12: =IF(I12<=$E$4,"A",IF(I12<=$E$5,"B","C")) -> A
A13: 6 | B13: 1540323 | C13: 17.06.0053 | D13: CABO ELETRICO FLEXIVEL DE COBRE ISOLADO 4X16 MM² 1KV NUM REF AFUMEX | E13: 3.8.1.017 - Instalações elétricas/telefônicas/lógica | F13: =COUNTIF(Base!$D$2:$D$2878,B13) -> 1 | G13: =SUMIF(Base!$D$2:$D$2878,B13,Base!$I$2:$I$2878) -> 340477.81 | H13: =IF($G$2849=0,0,G13/$G$2849) -> 0.022342912 | I13: =I12+H13 -> 0.17524538 | J13: =A13/2840 -> 0.0021126761 | K13: =IF(I13<=$E$4,"A",IF(I13<=$E$5,"B","C")) -> A
A14: 7 | B14: 1092910 | C14: 02.01.0080 | D14: TELA DO TIPO ALAMBRADO, MALHA DE ARAME EM AÇO GALVANIZADO. BWG 12 E ABERTURA DE 50MM (9,70M² POR PORTÃO) | E14: 3.8.1.002 - Telas e arames | F14: =COUNTIF(Base!$D$2:$D$2878,B14) -> 1 | G14: =SUMIF(Base!$D$2:$D$2878,B14,Base!$I$2:$I$2878) -> 319377.6 | H14: =IF($G$2849=0,0,G14/$G$2849) -> 0.020958269 | I14: =I13+H14 -> 0.19620365 | J14: =A14/2840 -> 0.0024647887 | K14: =IF(I14<=$E$4,"A",IF(I14<=$E$5,"B","C")) -> A
A15: 8 | B15: 1328133 | C15: 17.01.1205 | D15: CABO DE COBRE NU 120 MM², CLASSE 2A, TÊMPERA MEIO DURA, NBR 6524. | E15: 3.8.1.017 - Instalações elétricas/telefônicas/lógica | F15: =COUNTIF(Base!$D$2:$D$2878,B15) -> 2 | G15: =SUMIF(Base!$D$2:$D$2878,B15,Base!$I$2:$I$2878) -> 289781.22 | H15: =IF($G$2849=0,0,G15/$G$2849) -> 0.019016089 | I15: =I14+H15 -> 0.21521974 | J15: =A15/2840 -> 0.0028169014 | K15: =IF(I15<=$E$4,"A",IF(I15<=$E$5,"B","C")) -> A
A16: 9 | B16: 1328274 | C16: 17.01.1207 | D16: CABO BT 6MM² SOLAR, CONDUTOR DE COBRE FLEXÍVEL ESTANHADO, CAPA NA COR VERMELHA COM PROTEÇÃO UV | E16: 3.8.1.017 - Instalações elétricas/telefônicas/lógica | F16: =COUNTIF(Base!$D$2:$D$2878,B16) -> 1 | G16: =SUMIF(Base!$D$2:$D$2878,B16,Base!$I$2:$I$2878) -> 266529.6 | H16: =IF($G$2849=0,0,G16/$G$2849) -> 0.017490266 | I16: =I15+H16 -> 0.23271 | J16: =A16/2840 -> 0.0031690141 | K16: =IF(I16<=$E$4,"A",IF(I16<=$E$5,"B","C")) -> A
A17: 10 | B17: 1170016 | C17: 18.07.0094 | D17: RESERVATÓRIO DE 30.000 L EM PEAD | E17: 3.8.1.018 - Instalações hidráulicas/sanitárias/industriais | F17: =COUNTIF(Base!$D$2:$D$2878,B17) -> 2 | G17: =SUMIF(Base!$D$2:$D$2878,B17,Base!$I$2:$I$2878) -> 239772.49 | H17: =IF($G$2849=0,0,G17/$G$2849) -> 0.015734405 | I17: =I16+H17 -> 0.24844441 | J17: =A17/2840 -> 0.0035211268 | K17: =IF(I17<=$E$4,"A",IF(I17<=$E$5,"B","C")) -> A
A18: 11 | B18: 1485414 | C18: 17.24.0018 | D18: CAIXA DE INTERLIGAÇÃO EM AÇO INOX 304 PARA TP | E18: 3.8.1.017 - Instalações elétricas/telefônicas/lógica | F18: =COUNTIF(Base!$D$2:$D$2878,B18) -> 1 | G18: =SUMIF(Base!$D$2:$D$2878,B18,Base!$I$2:$I$2878) -> 198764.12 | H18: =IF($G$2849=0,0,G18/$G$2849) -> 0.013043344 | I18: =I17+H18 -> 0.26148775 | J18: =A18/2840 -> 0.0038732394 | K18: =IF(I18<=$E$4,"A",IF(I18<=$E$5,"B","C")) -> A
A19: 12 | B19: 1321831 | C19: 17.08.0218 | D19: QUADRO DE DISTRIBUIÇÃO DE CORRENTE CONTÍNUA, 2 ENTRADAS DE TENSÃO 125Vcc - 300A - 10kA | E19: 3.8.1.017 - Instalações elétricas/telefônicas/lógica | F19: =COUNTIF(Base!$D$2:$D$2878,B19) -> 1 | G19: =SUMIF(Base!$D$2:$D$2878,B19,Base!$I$2:$I$2878) -> 171047.93 | H19: =IF($G$2849=0,0,G19/$G$2849) -> 0.011224546 | I19: =I18+H19 -> 0.2727123 | J19: =A19/2840 -> 0.0042253521 | K19: =IF(I19<=$E$4,"A",IF(I19<=$E$5,"B","C")) -> A
A20: 13 | B20: 1321832 | C20: 17.08.0219 | D20: QUADRO DE DISTRIBUIÇÃO DE CORRENTE ALTERNADA, 2 ENTRADAS DE TENSÃO 380/220Vca - 300A - 10kA | E20: 3.8.1.017 - Instalações elétricas/telefônicas/lógica | F20: =COUNTIF(Base!$D$2:$D$2878,B20) -> 1 | G20: =SUMIF(Base!$D$2:$D$2878,B20,Base!$I$2:$I$2878) -> 169258.31 | H20: =IF($G$2849=0,0,G20/$G$2849) -> 0.011107107 | I20: =I19+H20 -> 0.2838194 | J20: =A20/2840 -> 0.0045774648 | K20: =IF(I20<=$E$4,"A",IF(I20<=$E$5,"B","C")) -> A
... A2847: 2840 | B2847: 1614274 | C2847: 17.03.0621 | D2847: BUCHA EXPANSAO NYLON N8 40MM | E2847: 3.8.1.017 - Instalações elétricas/telefônicas/lógica | F2847: =COUNTIF(Base!$D$2:$D$2878,B2847) -> 1 | G2847: =SUMIF(Base!$D$2:$D$2878,B2847,Base!$I$2:$I$2878) -> 0.48 | H2847: =IF($G$2849=0,0,G2847/$G$2849) -> 3.1498669e-08 | I2847: =I2846+H2847 -> 1 | J2847: =A2847/2840 -> 1 | K2847: =IF(I2847<=$E$4,"A",IF(I2847<=$E$5,"B","C")) -> C
F2849: TOTAL | G2849: =SUM(G8:G2847) -> 15238739
F2850: Conferência vs Base | G2850: =G2849-SUM(Base!$I$2:$I$2878) -> 0

Sheet Análises
A1: TABELAS DE APOIO DO DASHBOARD (fórmulas – não editar)
A3: Classe | B3: Nº itens | C3: % itens | D3: Valor (R$) | E3: % valor
A4: A | B4: =COUNTIF('Curva ABC'!$K$8:$K$2847,A4) -> 255 | C4: =B4/$B$7 -> 0.089788732 | D4: =SUMIF('Curva ABC'!$K$8:$K$2847,A4,'Curva ABC'!$G$8:$G$2847) -> 12188258 | E4: =D4/$D$7 -> 0.79982061
A5: B | B5: =COUNTIF('Curva ABC'!$K$8:$K$2847,A5) -> 609 | C5: =B5/$B$7 -> 0.21443662 | D5: =SUMIF('Curva ABC'!$K$8:$K$2847,A5,'Curva ABC'!$G$8:$G$2847) -> 2288357.1 | E5: =D5/$D$7 -> 0.15016709
A6: C | B6: =COUNTIF('Curva ABC'!$K$8:$K$2847,A6) -> 1976 | C6: =B6/$B$7 -> 0.69577465 | D6: =SUMIF('Curva ABC'!$K$8:$K$2847,A6,'Curva ABC'!$G$8:$G$2847) -> 762124.34 | E6: =D6/$D$7 -> 0.050012296
A7: Total | B7: =SUM(B4:B6) -> 2840 | C7: =SUM(C4:C6) -> 1 | D7: =SUM(D4:D6) -> 15238739 | E7: =SUM(E4:E6) -> 1
A10: CODLOC | B10: Local | C10: Nº linhas | D10: Valor (R$) | E10: % valor
A11: 0335 | B11: USO E CONSUMO | C11: =COUNTIF(Base!$B$2:$B$2878,A11) -> 2731 | D11: =SUMIF(Base!$B$2:$B$2878,A11,Base!$I$2:$I$2878) -> 10186546 | E11: =D11/$D$16 -> 0.66846383
A12: 0337 | B12: FAT. DIR. CLIENTE | C12: =COUNTIF(Base!$B$2:$B$2878,A12) -> 30 | D12: =SUMIF(Base!$B$2:$B$2878,A12,Base!$I$2:$I$2878) -> 2926675 | E12: =D12/$D$16 -> 0.19205493
A13: 0338 | B13: IMOBILIZADO | C13: =COUNTIF(Base!$B$2:$B$2878,A13) -> 91 | D13: =SUMIF(Base!$B$2:$B$2878,A13,Base!$I$2:$I$2878) -> 2117923.5 | E13: =D13/$D$16 -> 0.13898286
A14: 0336 | B14: FAT. DIR. TERCEIRO | C14: =COUNTIF(Base!$B$2:$B$2878,A14) -> 23 | D14: =SUMIF(Base!$B$2:$B$2878,A14,Base!$I$2:$I$2878) -> 7096.7 | E14: =D14/$D$16 -> 0.00046570125
A15: 0346 | B15: ESTOQUE MATRIZ FIL 1 | C15: =COUNTIF(Base!$B$2:$B$2878,A15) -> 2 | D15: =SUMIF(Base!$B$2:$B$2878,A15,Base!$I$2:$I$2878) -> 498 | E15: =D15/$D$16 -> 3.2679869e-05
A16: Total | C16: =SUM(C11:C15) -> 2877 | D16: =SUM(D11:D15) -> 15238739 | E16: =SUM(E11:E15) -> 1
A19: CODLOC | B19: Local | C19: Classe A (R$) | D19: Classe B (R$) | E19: Classe C (R$) | F19: Total (R$)
A20: 0335 | B20: =B11 -> USO E CONSUMO | C20: =SUMIFS(Base!$I$2:$I$2878,Base!$B$2:$B$2878,$A20,Base!$K$2:$K$2878,"A") -> 7352689.3 | D20: =SUMIFS(Base!$I$2:$I$2878,Base!$B$2:$B$2878,$A20,Base!$K$2:$K$2878,"B") -> 2089884.5 | E20: =SUMIFS(Base!$I$2:$I$2878,Base!$B$2:$B$2878,$A20,Base!$K$2:$K$2878,"C") -> 743972.25 | F20: =SUM(C20:E20) -> 10186546
A21: 0337 | B21: =B12 -> FAT. DIR. CLIENTE | C21: =SUMIFS(Base!$I$2:$I$2878,Base!$B$2:$B$2878,$A21,Base!$K$2:$K$2878,"A") -> 2911160.2 | D21: =SUMIFS(Base!$I$2:$I$2878,Base!$B$2:$B$2878,$A21,Base!$K$2:$K$2878,"B") -> 11922.99 | E21: =SUMIFS(Base!$I$2:$I$2878,Base!$B$2:$B$2878,$A21,Base!$K$2:$K$2878,"C") -> 3591.81 | F21: =SUM(C21:E21) -> 2926675
A22: 0338 | B22: =B13 -> IMOBILIZADO | C22: =SUMIFS(Base!$I$2:$I$2878,Base!$B$2:$B$2878,$A22,Base!$K$2:$K$2878,"A") -> 1924408.3 | D22: =SUMIFS(Base!$I$2:$I$2878,Base!$B$2:$B$2878,$A22,Base!$K$2:$K$2878,"B") -> 185473.59 | E22: =SUMIFS(Base!$I$2:$I$2878,Base!$B$2:$B$2878,$A22,Base!$K$2:$K$2878,"C") -> 8041.58 | F22: =SUM(C22:E22) -> 2117923.5
A23: 0336 | B23: =B14 -> FAT. DIR. TERCEIRO | C23: =SUMIFS(Base!$I$2:$I$2878,Base!$B$2:$B$2878,$A23,Base!$K$2:$K$2878,"A") -> 0 | D23: =SUMIFS(Base!$I$2:$I$2878,Base!$B$2:$B$2878,$A23,Base!$K$2:$K$2878,"B") -> 1076 | E23: =SUMIFS(Base!$I$2:$I$2878,Base!$B$2:$B$2878,$A23,Base!$K$2:$K$2878,"C") -> 6020.7 | F23: =SUM(C23:E23) -> 7096.7
A24: 0346 | B24: =B15 -> ESTOQUE MATRIZ FIL 1 | C24: =SUMIFS(Base!$I$2:$I$2878,Base!$B$2:$B$2878,$A24,Base!$K$2:$K$2878,"A") -> 0 | D24: =SUMIFS(Base!$I$2:$I$2878,Base!$B$2:$B$2878,$A24,Base!$K$2:$K$2878,"B") -> 0 | E24: =SUMIFS(Base!$I$2:$I$2878,Base!$B$2:$B$2878,$A24,Base!$K$2:$K$2878,"C") -> 498 | F24: =SUM(C24:E24) -> 498
A28: Natureza (top 10) | B28: Nº itens | C28: Valor (R$) | D28: % valor
A29: 3.8.1.017 - Instalações elétricas/telefônicas/lógica | B29: =COUNTIF('Curva ABC'!$E$8:$E$2847,A29) -> 665 | C29: =SUMIF('Curva ABC'!$E$8:$E$2847,A29,'Curva ABC'!$G$8:$G$2847) -> 5664327.3 | D29: =C29/'Curva ABC'!$G$2849 -> 0.37170577
A30: 6.1.2.001 - Equipamentos | B30: =COUNTIF('Curva ABC'!$E$8:$E$2847,A30) -> 69 | C30: =SUMIF('Curva ABC'!$E$8:$E$2847,A30,'Curva ABC'!$G$8:$G$2847) -> 1473726.1 | D30: =C30/'Curva ABC'!$G$2849 -> 0.096709185
A31: 3.8.1.018 - Instalações hidráulicas/sanitárias/industriais | B31: =COUNTIF('Curva ABC'!$E$8:$E$2847,A31) -> 243 | C31: =SUMIF('Curva ABC'!$E$8:$E$2847,A31,'Curva ABC'!$G$8:$G$2847) -> 1077720.8 | D31: =C31/'Curva ABC'!$G$2849 -> 0.070722437
A32: 3.7.1.018 - Serviço de instalações elétricas/telefônica/lógica | B32: =COUNTIF('Curva ABC'!$E$8:$E$2847,A32) -> 8 | C32: =SUMIF('Curva ABC'!$E$8:$E$2847,A32,'Curva ABC'!$G$8:$G$2847) -> 702645.3 | D32: =C32/'Curva ABC'!$G$2849 -> 0.046109149
A33: 3.8.1.009 - Artefatos pré-moldados de concreto | B33: =COUNTIF('Curva ABC'!$E$8:$E$2847,A33) -> 30 | C33: =SUMIF('Curva ABC'!$E$8:$E$2847,A33,'Curva ABC'!$G$8:$G$2847) -> 557131.23 | D33: =C33/'Curva ABC'!$G$2849 -> 0.036560192
A34: 3.8.1.022 - Elementos de fixação | B34: =COUNTIF('Curva ABC'!$E$8:$E$2847,A34) -> 280 | C34: =SUMIF('Curva ABC'!$E$8:$E$2847,A34,'Curva ABC'!$G$8:$G$2847) -> 478791.78 | D34: =C34/'Curva ABC'!$G$2849 -> 0.031419383
A35: 3.8.1.001 - Aços e trefilados | B35: =COUNTIF('Curva ABC'!$E$8:$E$2847,A35) -> 88 | C35: =SUMIF('Curva ABC'!$E$8:$E$2847,A35,'Curva ABC'!$G$8:$G$2847) -> 463918.55 | D35: =C35/'Curva ABC'!$G$2849 -> 0.030443368
A36: 4.1.1.008 - Mobiliário e acessórios | B36: =COUNTIF('Curva ABC'!$E$8:$E$2847,A36) -> 29 | C36: =SUMIF('Curva ABC'!$E$8:$E$2847,A36,'Curva ABC'!$G$8:$G$2847) -> 455464.17 | D36: =C36/'Curva ABC'!$G$2849 -> 0.029888573
A37: 4.3.4.001 - Equipamento de proteção individual | B37: =COUNTIF('Curva ABC'!$E$8:$E$2847,A37) -> 183 | C37: =SUMIF('Curva ABC'!$E$8:$E$2847,A37,'Curva ABC'!$G$8:$G$2847) -> 437756.61 | D37: =C37/'Curva ABC'!$G$2849 -> 0.028726563
A38: 4.1.1.009 - Eletro eletrônico e acessórios | B38: =COUNTIF('Curva ABC'!$E$8:$E$2847,A38) -> 40 | C38: =SUMIF('Curva ABC'!$E$8:$E$2847,A38,'Curva ABC'!$G$8:$G$2847) -> 370257.82 | D38: =C38/'Curva ABC'!$G$2849 -> 0.024297143
A39: Demais naturezas | C39: ='Curva ABC'!$G$2849-SUM(C29:C38) -> 3556999.7 | D39: =C39/'Curva ABC'!$G$2849 -> 0.23341824
A43: Top 10 itens | B43: Valor (R$) | C43: % valor
A44: ='Curva ABC'!C8&" - "&LEFT('Curva ABC'!D8,38) -> 17.01.1200 - CABO UNIPOLAR DE ALUMÍNIO, CLASSE 0,6/ | B44: ='Curva ABC'!G8 -> 689877.92 | C44: ='Curva ABC'!H8 -> 0.045271325
A45: ='Curva ABC'!C9&" - "&LEFT('Curva ABC'!D9,38) -> 32.13.0045 - CARPA DORMITÓRIO COM DIVISÓRIA EM PVC | B45: ='Curva ABC'!G9 -> 595000 | C45: ='Curva ABC'!H9 -> 0.039045225
A46: ='Curva ABC'!C10&" - "&LEFT('Curva ABC'!D10,38) -> 17.01.1206 - CABO BT 6MM² SOLAR, CONDUTOR DE COBRE | B46: ='Curva ABC'!G10 -> 355560.3 | C46: ='Curva ABC'!H10 -> 0.023332658
A47: ='Curva ABC'!C11&" - "&LEFT('Curva ABC'!D11,38) -> 17.01.0846 - CABO DE COBRE NU 50MM²,TÊMPERA MEIO DU | B47: ='Curva ABC'!G11 -> 348968.62 | C47: ='Curva ABC'!H11 -> 0.022900098
A48: ='Curva ABC'!C12&" - "&LEFT('Curva ABC'!D12,38) -> 17.01.1203 - CABO DE COBRE MONOPOLAR 240 MM², CLASS | B48: ='Curva ABC'!G12 -> 340633.99 | C48: ='Curva ABC'!H12 -> 0.022353161
A49: ='Curva ABC'!C13&" - "&LEFT('Curva ABC'!D13,38) -> 17.06.0053 - CABO ELETRICO FLEXIVEL DE COBRE ISOLAD | B49: ='Curva ABC'!G13 -> 340477.81 | C49: ='Curva ABC'!H13 -> 0.022342912
A50: ='Curva ABC'!C14&" - "&LEFT('Curva ABC'!D14,38) -> 02.01.0080 - TELA DO TIPO ALAMBRADO, MALHA DE ARAME | B50: ='Curva ABC'!G14 -> 319377.6 | C50: ='Curva ABC'!H14 -> 0.020958269
A51: ='Curva ABC'!C15&" - "&LEFT('Curva ABC'!D15,38) -> 17.01.1205 - CABO DE COBRE NU 120 MM², CLASSE 2A, T | B51: ='Curva ABC'!G15 -> 289781.22 | C51: ='Curva ABC'!H15 -> 0.019016089
...

Sheet Base
A1: Aba origem | B1: CODLOC | C1: Local | D1: IDPRD | E1: Código | F1: Descrição | G1: Unid. | H1: Saldo físico | I1: Saldo financeiro (R$) | J1: Natureza | K1: Classe ABC
A2: Uso e Consumo | B2: ='Uso e Consumo'!A2 -> 0335 | C2: ='Uso e Consumo'!B2 -> UFV NORONHA VERDE - USO E CONSUMO | D2: ='Uso e Consumo'!C2 -> 387747 | E2: ='Uso e Consumo'!D2 -> 17.01.0846 | F2: ='Uso e Consumo'!E2 -> CABO DE COBRE NU 50MM²,TÊMPERA MEIO DURA,7 FIOS E ENCORDOAMENTO CLASSE 2A | G2: ='Uso e Consumo'!J2 -> M | H2: ='Uso e Consumo'!F2 -> 8080 | I2: ='Uso e Consumo'!G2 -> 348968.62 | J2: ='Uso e Consumo'!M2 -> 3.8.1.017 - Instalações elétricas/telefônicas/lógica | K2: =INDEX('Curva ABC'!$K$8:$K$2847,MATCH(D2,'Curva ABC'!$B$8:$B$2847,0)) -> A
A3: Uso e Consumo | B3: ='Uso e Consumo'!A3 -> 0335 | C3: ='Uso e Consumo'!B3 -> UFV NORONHA VERDE - USO E CONSUMO | D3: ='Uso e Consumo'!C3 -> 1328095 | E3: ='Uso e Consumo'!D3 -> 17.01.1203 | F3: ='Uso e Consumo'!E3 -> CABO DE COBRE MONOPOLAR 240 MM², CLASSE 2, 8,7/15 KV, ISOLAÇÃO EPR, COBERTURA PVC PRETO, BLINDAGEM 25 MM² | G3: ='Uso e Consumo'!J3 -> M | H3: ='Uso e Consumo'!F3 -> 1000 | I3: ='Uso e Consumo'!G3 -> 340633.99 | J3: ='Uso e Consumo'!M3 -> 3.8.1.017 - Instalações elétricas/telefônicas/lógica | K3: =INDEX('Curva ABC'!$K$8:$K$2847,MATCH(D3,'Curva ABC'!$B$8:$B$2847,0)) -> A
A4: Uso e Consumo | B4: ='Uso e Consumo'!A4 -> 0335 | C4: ='Uso e Consumo'!B4 -> UFV NORONHA VERDE - USO E CONSUMO | D4: ='Uso e Consumo'!C4 -> 1092910 | E4: ='Uso e Consumo'!D4 -> 02.01.0080 | F4: ='Uso e Consumo'!E4 -> TELA DO TIPO ALAMBRADO, MALHA DE ARAME EM AÇO GALVANIZADO. BWG 12 E ABERTURA DE 50MM (9,70M² POR PORTÃO) | G4: ='Uso e Consumo'!J4 -> M2 | H4: ='Uso e Consumo'!F4 -> 13307.4 | I4: ='Uso e Consumo'!G4 -> 319377.6 | J4: ='Uso e Consumo'!M4 -> 3.8.1.002 - Telas e arames | K4: =INDEX('Curva ABC'!$K$8:$K$2847,MATCH(D4,'Curva ABC'!$B$8:$B$2847,0)) -> A
A5: Uso e Consumo | B5: ='Uso e Consumo'!A5 -> 0335 | C5: ='Uso e Consumo'!B5 -> UFV NORONHA VERDE - USO E CONSUMO | D5: ='Uso e Consumo'!C5 -> 1485414 | E5: ='Uso e Consumo'!D5 -> 17.24.0018 | F5: ='Uso e Consumo'!E5 -> CAIXA DE INTERLIGAÇÃO EM AÇO INOX 304 PARA TP | G5: ='Uso e Consumo'!J5 -> UN | H5: ='Uso e Consumo'!F5 -> 13 | I5: ='Uso e Consumo'!G5 -> 198764.12 | J5: ='Uso e Consumo'!M5 -> 3.8.1.017 - Instalações elétricas/telefônicas/lógica | K5: =INDEX('Curva ABC'!$K$8:$K$2847,MATCH(D5,'Curva ABC'!$B$8:$B$2847,0)) -> A
A6: Uso e Consumo | B6: ='Uso e Consumo'!A6 -> 0335 | C6: ='Uso e Consumo'!B6 -> UFV NORONHA VERDE - USO E CONSUMO | D6: ='Uso e Consumo'!C6 -> 1321831 | E6: ='Uso e Consumo'!D6 -> 17.08.0218 | F6: ='Uso e Consumo'!E6 -> QUADRO DE DISTRIBUIÇÃO DE CORRENTE CONTÍNUA, 2 ENTRADAS DE TENSÃO 125Vcc - 300A - 10kA | G6: ='Uso e Consumo'!J6 -> UN | H6: ='Uso e Consumo'!F6 -> 2 | I6: ='Uso e Consumo'!G6 -> 171047.93 | J6: ='Uso e Consumo'!M6 -> 3.8.1.017 - Instalações elétricas/telefônicas/lógica | K6: =INDEX('Curva ABC'!$K$8:$K$2847,MATCH(D6,'Curva ABC'!$B$8:$B$2847,0)) -> A
A7: Uso e Consumo | B7: ='Uso e Consumo'!A7 -> 0335 | C7: ='Uso e Consumo'!B7 -> UFV NORONHA VERDE - USO E CONSUMO | D7: ='Uso e Consumo'!C7 -> 1321832 | E7: ='Uso e Consumo'!D7 -> 17.08.0219 | F7: ='Uso e Consumo'!E7 -> QUADRO DE DISTRIBUIÇÃO DE CORRENTE ALTERNADA, 2 ENTRADAS DE TENSÃO 380/220Vca - 300A - 10kA | G7: ='Uso e Consumo'!J7 -> UN | H7: ='Uso e Consumo'!F7 -> 2 | I7: ='Uso e Consumo'!G7 -> 169258.31 | J7: ='Uso e Consumo'!M7 -> 3.8.1.017 - Instalações elétricas/telefônicas/lógica | K7: =INDEX('Curva ABC'!$K$8:$K$2847,MATCH(D7,'Curva ABC'!$B$8:$B$2847,0)) -> A
A8: Uso e Consumo | B8: ='Uso e Consumo'!A8 -> 0335 | C8: ='Uso e Consumo'!B8 -> UFV NORONHA VERDE - USO E CONSUMO | D8: ='Uso e Consumo'!C8 -> 57985 | E8: ='Uso e Consumo'!D8 -> 09.19.0032 | F8: ='Uso e Consumo'!E8 -> PISO INTERTRAVADO CONCRETO RETANGULAR 10,00CM X 20,00CM X 8,00CM NATURAL | G8: ='Uso e Consumo'!J8 -> M2 | H8: ='Uso e Consumo'!F8 -> 2587.5 | I8: ='Uso e Consumo'!G8 -> 163012.5 | J8: ='Uso e Consumo'!M8 -> 3.8.1.010 - Revestimentos e pisos | K8: =INDEX('Curva ABC'!$K$8:$K$2847,MATCH(D8,'Curva ABC'!$B$8:$B$2847,0)) -> A
A9: Uso e Consumo | B9: ='Uso e Consumo'!A9 -> 0335 | C9: ='Uso e Consumo'!B9 -> UFV NORONHA VERDE - USO E CONSUMO | D9: ='Uso e Consumo'!C9 -> 742688 | E9: ='Uso e Consumo'!D9 -> 09.16.0030 | F9: ='Uso e Consumo'!E9 -> MOURÃO DE CONCRETO 10 X 10 CM NOS VÉRTICES, E A CADA 100 M | G9: ='Uso e Consumo'!J9 -> UN | H9: ='Uso e Consumo'!F9 -> 2100 | I9: ='Uso e Consumo'!G9 -> 159390 | J9: ='Uso e Consumo'!M9 -> 3.8.1.009 - Artefatos pré-moldados de concreto | K9: =INDEX('Curva ABC'!$K$8:$K$2847,MATCH(D9,'Curva ABC'!$B$8:$B$2847,0)) -> A
A10: Uso e Consumo | B10: ='Uso e Consumo'!A10 -> 0335 | C10: ='Uso e Consumo'!B10 -> UFV NORONHA VERDE - USO E CONSUMO | D10: ='Uso e Consumo'!C10 -> 1322477 | E10: ='Uso e Consumo'!D10 -> 17.01.1198 | F10: ='Uso e Consumo'!E10 -> CABO UNIPOLAR DE COBRE, CLASSE 8,7/15KV, ISOL. HEPR, COB. PVC SEÇÃO 150MM², BLINDAGEM 25MM². REF PRYSMIAN OU SIMILAR | G10: ='Uso e Consumo'!J10 -> M | H10: ='Uso e Consumo'!F10 -> 804 | I10: ='Uso e Consumo'!G10 -> 151354.5 | J10: ='Uso e Consumo'!M10 -> 3.8.1.017 - Instalações elétricas/telefônicas/lógica | K10: =INDEX('Curva ABC'!$K$8:$K$2847,MATCH(D10,'Curva ABC'!$B$8:$B$2847,0)) -> A
A11: Uso e Consumo | B11: ='Uso e Consumo'!A11 -> 0335 | C11: ='Uso e Consumo'!B11 -> UFV NORONHA VERDE - USO E CONSUMO | D11: ='Uso e Consumo'!C11 -> 884974 | E11: ='Uso e Consumo'!D11 -> 17.22.0110 | F11: ='Uso e Consumo'!E11 -> ALÇA PREFORMADA PARA AMARRAÇÃO DO CABO NU | G11: ='Uso e Consumo'!J11 -> UND | H11: ='Uso e Consumo'!F11 -> 600 | I11: ='Uso e Consumo'!G11 -> 142639.77 | J11: ='Uso e Consumo'!M11 -> 3.8.1.017 - Instalações elétricas/telefônicas/lógica | K11: =INDEX('Curva ABC'!$K$8:$K$2847,MATCH(D11,'Curva ABC'!$B$8:$B$2847,0)) -> A
A12: Uso e Consumo | B12: ='Uso e Consumo'!A12 -> 0335 | C12: ='Uso e Consumo'!B12 -> UFV NORONHA VERDE - USO E CONSUMO | D12: ='Uso e Consumo'!C12 -> 1328795 | E12: ='Uso e Consumo'!D12 -> 32.07.0231 | F12: ='Uso e Consumo'!E12 -> RETIFICADOR 380VCA 3F - 125 VCC / 48 VCC / 12 VCC CHAVEADO EM ALTA FREQUÊNCIA 11,11 KVA | G12: ='Uso e Consumo'!J12 -> UN | H12: ='Uso e Consumo'!F12 -> 2 | I12: ='Uso e Consumo'!G12 -> 137108.08 | J12: ='Uso e Consumo'!M12 -> 6.1.2.001 - Equipamentos | K12: =INDEX('Curva ABC'!$K$8:$K$2847,MATCH(D12,'Curva ABC'!$B$8:$B$2847,0)) -> A
A13: Uso e Consumo | B13: ='Uso e Consumo'!A13 -> 0335 | C13: ='Uso e Consumo'!B13 -> UFV NORONHA VERDE - USO E CONSUMO | D13: ='Uso e Consumo'!C13 -> 53717 | E13: ='Uso e Consumo'!D13 -> 18.07.0053 | F13: ='Uso e Consumo'!E13 -> CAIXA D´AGUA POLIETILENO 10.000L C/ TAMPA | G13: ='Uso e Consumo'!J13 -> UN | H13: ='Uso e Consumo'!F13 -> 10 | I13: ='Uso e Consumo'!G13 -> 119800 | J13: ='Uso e Consumo'!M13 -> 3.8.1.018 - Instalações hidráulicas/sanitárias/industriais | K13: =INDEX('Curva ABC'!$K$8:$K$2847,MATCH(D13,'Curva ABC'!$B$8:$B$2847,0)) -> A
... A2732: Uso e Consumo | B2732: ='Uso e Consumo'!A2732 -> 0335 | C2732: ='Uso e Consumo'!B2732 -> UFV NORONHA VERDE - USO E CONSUMO | D2732: ='Uso e Consumo'!C2732 -> 1614274 | E2732: ='Uso e Consumo'!D2732 -> 17.03.0621 | F2732: ='Uso e Consumo'!E2732 -> BUCHA EXPANSAO NYLON N8 40MM | G2732: ='Uso e Consumo'!J2732 -> UN | H2732: ='Uso e Consumo'!F2732 -> 6 | I2732: ='Uso e Consumo'!G2732 -> 0.48 | J2732: ='Uso e Consumo'!M2732 -> 3.8.1.017 - Instalações elétricas/telefônicas/lógica | K2732: =INDEX('Curva ABC'!$K$8:$K$2847,MATCH(D2732,'Curva ABC'!$B$8:$B$2847,0)) -> C
A2733: Fat Dir Terceiro | B2733: ='Fat Dir Terceiro'!A2 -> 0336 | C2733: ='Fat Dir Terceiro'!B2 -> UFV NORONHA VERDE - FAT. DIR. TERCEIRO | D2733: ='Fat Dir Terceiro'!C2 -> 17864 | E2733: ='Fat Dir Terceiro'!D2 -> 24.04.0007 | F2733: ='Fat Dir Terceiro'!E2 -> PRUMO PAREDE AÇO SAE 1020 CORDAO NYLON TAÇO MADEIRA 400,00G | G2733: ='Fat Dir Terceiro'!J2 -> UN | H2733: ='Fat Dir Terceiro'!F2 -> 10 | I2733: ='Fat Dir Terceiro'!G2 -> 340 | J2733: ='Fat Dir Terceiro'!M2 -> 3.8.2.001 - Ferramentas medição/aferição | K2733: =INDEX('Curva ABC'!$K$8:$K$2847,MATCH(D2733,'Curva ABC'!$B$8:$B$2847,0)) -> C
A2734: Fat Dir Terceiro | B2734: ='Fat Dir Terceiro'!A3 -> 0336 | C2734: ='Fat Dir Terceiro'!B3 -> UFV NORONHA VERDE - FAT. DIR. TERCEIRO | D2734: ='Fat Dir Terceiro'!C3 -> 17885 | E2734: ='Fat Dir Terceiro'!D3 -> 24.07.0002 | F2734: ='Fat Dir Terceiro'!E3 -> TRENA CURTA 8,00M CAIXA FECHADA PLASTICA FITA AÇO TEMPERADO | G2734: ='Fat Dir Terceiro'!J3 -> UN | H2734: ='Fat Dir Terceiro'!F3 -> 12 | I2734: ='Fat Dir Terceiro'!G3 -> 528 | J2734: ='Fat Dir Terceiro'!M3 -> 3.8.2.001 - Ferramentas medição/aferição | K2734: =INDEX('Curva ABC'!$K$8:$K$2847,MATCH(D2734,'Curva ABC'!$B$8:$B$2847,0)) -> B
A2735: Fat Dir Terceiro | B2735: ='Fat Dir Terceiro'!A4 -> 0336 | C2735: ='Fat Dir Terceiro'!B4 -> UFV NORONHA VERDE - FAT. DIR. TERCEIRO | D2735: ='Fat Dir Terceiro'!C4 -> 18164 | E2735: ='Fat Dir Terceiro'!D4 -> 24.21.0001 | F2735: ='Fat Dir Terceiro'!E4 -> SERROTE PROFISSIONAL 18" CORPO AÇO CARBONO CABO MADEIRA 9 DENTES P/POLEGADA | G2735: ='Fat Dir Terceiro'!J4 -> UN | H2735: ='Fat Dir Terceiro'!F4 -> 8 | I2735: ='Fat Dir Terceiro'!G4 -> 264 | J2735: ='Fat Dir Terceiro'!M4 -> 3.8.2.002 - Ferramentas manuais | K2735: =INDEX('Curva ABC'!$K$8:$K$2847,MATCH(D2735,'Curva ABC'!$B$8:$B$2847,0)) -> C
A2736: Fat Dir Terceiro | B2736: ='Fat Dir Terceiro'!A5 -> 0336 | C2736: ='Fat Dir Terceiro'!B5 -> UFV NORONHA VERDE - FAT. DIR. TERCEIRO | D2736: ='Fat Dir Terceiro'!C5 -> 21111 | E2736: ='Fat Dir Terceiro'!D5 -> 30.02.0043 | F2736: ='Fat Dir Terceiro'!E5 -> LIMPA CONTATO ELÉTRICO/ELETÔNICO 300ML | G2736: ='Fat Dir Terceiro'!J5 -> UN | H2736: ='Fat Dir Terceiro'!F5 -> 12 | I2736: ='Fat Dir Terceiro'!G5 -> 194.52 | J2736: ='Fat Dir Terceiro'!M5 -> 4.1.1.002 - Material expediente | K2736: =INDEX('Curva ABC'!$K$8:$K$2847,MATCH(D2736,'Curva ABC'!$B$8:$B$2847,0)) -> C
A2737: Fat Dir Terceiro | B2737: ='Fat Dir Terceiro'!A6 -> 0336 | C2737: ='Fat Dir Terceiro'!B6 -> UFV NORONHA VERDE - FAT. DIR. TERCEIRO | D2737: ='Fat Dir Terceiro'!C6 -> 21297 | E2737: ='Fat Dir Terceiro'!D6 -> 24.28.0001 | F2737: ='Fat Dir Terceiro'!E6 -> LÁPIS PARA CARPINTEIRO | G2737: ='Fat Dir Terceiro'!J6 -> UN | H2737: ='Fat Dir Terceiro'!F6 -> 50 | I2737: ='Fat Dir Terceiro'!G6 -> 87.5 | J2737: ='Fat Dir Terceiro'!M6 -> 3.8.2.002 - Ferramentas manuais | K2737: =INDEX('Curva ABC'!$K$8:$K$2847,MATCH(D2737,'Curva ABC'!$B$8:$B$2847,0)) -> C
A2738: Fat Dir Terceiro | B2738: ='Fat Dir Terceiro'!A7 -> 0336 | C2738: ='Fat Dir Terceiro'!B7 -> UFV NORONHA VERDE - FAT. DIR. TERCEIRO | D2738: ='Fat Dir Terceiro'!C7 -> 21488 | E2738: ='Fat Dir Terceiro'!D7 -> 16.05.0076 | F2738: ='Fat Dir Terceiro'!E7 -> TRINCHA 4" N500 CABO DE PVC | G2738: ='Fat Dir Terceiro'!J7 -> UN | H2738: ='Fat Dir Terceiro'!F7 -> 10 | I2738: ='Fat Dir Terceiro'!G7 -> 115 | J2738: ='Fat Dir Terceiro'!M7 -> 3.8.1.016 - Pinturas | K2738: =INDEX('Curva ABC'!$K$8:$K$2847,MATCH(D2738,'Curva ABC'!$B$8:$B$2847,0)) -> C
A2739: Fat Dir Terceiro | B2739: ='Fat Dir Terceiro'!A8 -> 0336 | C2739: ='Fat Dir Terceiro'!B8 -> UFV NORONHA VERDE - FAT. DIR. TERCEIRO | D2739: ='Fat Dir Terceiro'!C8 -> 22252 | E2739: ='Fat Dir Terceiro'!D8 -> 25.10.0021 | F2739: ='Fat Dir Terceiro'!E8 -> LINHA NYLON P/ PEDREIRO 1,0MM X 100M | G2739: ='Fat Dir Terceiro'!J8 -> UN | H2739: ='Fat Dir Terceiro'!F8 -> 40 | I2739: ='Fat Dir Terceiro'!G8 -> 680 | J2739: ='Fat Dir Terceiro'!M8 -> 3.8.2.006 - Utensílios | K2739: =INDEX('Curva ABC'!$K$8:$K$2847,MATCH(D2739,'Curva ABC'!$B$8:$B$2847,0)) -> C
A2740: Fat Dir Terceiro | B2740: ='Fat Dir Terceiro'!A9 -> 0336 | C2740: ='Fat Dir Terceiro'!B9 -> UFV NORONHA VERDE - FAT. DIR. TERCEIRO | D2740: ='Fat Dir Terceiro'!C9 -> 22375 | E2740: ='Fat Dir Terceiro'!D9 -> 25.20.0001 | F2740: ='Fat Dir Terceiro'!E9 -> ARCO DE SERRA FIXO 12 POL REF.STARRET-140 | G2740: ='Fat Dir Terceiro'!J9 -> UN | H2740: ='Fat Dir Terceiro'!F9 -> 10 | I2740: ='Fat Dir Terceiro'!G9 -> 548 | J2740: ='Fat Dir Terceiro'!M9 -> 3.8.2.006 - Utensílios | K2740: =INDEX('Curva ABC'!$K$8:$K$2847,MATCH(D2740,'Curva ABC'!$B$8:$B$2847,0)) -> B
A2741: Fat Dir Terceiro | B2741: ='Fat Dir Terceiro'!A10 -> 0336 | C2741: ='Fat Dir Terceiro'!B10 -> UFV NORONHA VERDE - FAT. DIR. TERCEIRO | D2741: ='Fat Dir Terceiro'!C10 -> 23269 | E2741: ='Fat Dir Terceiro'!D10 -> 16.05.0081 | F2741: ='Fat Dir Terceiro'!E10 -> TRINCHA 1.1/2 | G2741: ='Fat Dir Terceiro'!J10 -> UN | H2741: ='Fat Dir Terceiro'!F10 -> 10 | I2741: ='Fat Dir Terceiro'!G10 -> 38 | J2741: ='Fat Dir Terceiro'!M10 -> 3.8.1.016 - Pinturas | K2741: =INDEX('Curva ABC'!$K$8:$K$2847,MATCH(D2741,'Curva ABC'!$B$8:$B$2847,0)) -> C
A2742: Fat Dir Terceiro | B2742: ='Fat Dir Terceiro'!A11 -> 0336 | C2742: ='Fat Dir Terceiro'!B11 -> UFV NORONHA VERDE - FAT. DIR. TERCEIRO | D2742: ='Fat Dir Terceiro'!C11 -> 23796 | E2742: ='Fat Dir Terceiro'!D11 -> 25.03.0171 | F2742: ='Fat Dir Terceiro'!E11 -> BROCA CONCRETO 8MM | G2742: ='Fat Dir Terceiro'!J11 -> UN | H2742: ='Fat Dir Terceiro'!F11 -> 12 | I2742: ='Fat Dir Terceiro'!G11 -> 81.24 | J2742: ='Fat Dir Terceiro'!M11 -> 3.8.2.004 - Consumíveis para corte, perfuração e desbaste | K2742: =INDEX('Curva ABC'!$K$8:$K$2847,MATCH(D2742,'Curva ABC'!$B$8:$B$2847,0)) -> C
A2743: Fat Dir Terceiro | B2743: ='Fat Dir Terceiro'!A12 -> 0336 | C2743: ='Fat Dir Terceiro'!B12 -> UFV NORONHA VERDE - FAT. DIR. TERCEIRO | D2743: ='Fat Dir Terceiro'!C12 -> 24365 | E2743: ='Fat Dir Terceiro'!D12 -> 25.03.0178 | F2743: ='Fat Dir Terceiro'!E12 -> BROCA CONCRETO 12MM | G2743: ='Fat Dir Terceiro'!J12 -> UN | H2743: ='Fat Dir Terceiro'!F12 -> 24 | I2743: ='Fat Dir Terceiro'!G12 -> 287.28 | J2743: ='Fat Dir Terceiro'!M12 -> 3.8.2.004 - Consumíveis para corte, perfuração e desbaste | K2743: =INDEX('Curva ABC'!$K$8:$K$2847,MATCH(D2743,'Curva ABC'!$B$8:$B$2847,0)) -> C
A2744: Fat Dir Terceiro | B2744: ='Fat Dir Terceiro'!A13 -> 0336 | C2744: ='Fat Dir Terceiro'!B13 -> UFV NORONHA VERDE - FAT. DIR. TERCEIRO | D2744: ='Fat Dir Terceiro'!C13 -> 54662 | E2744: ='Fat Dir Terceiro'!D13 -> 24.33.0003 | F2744: ='Fat Dir Terceiro'!E13 -> BLOCO DE ESPUMA 12,00 CM X 6,00 CM X 22,00 CM | G2744: ='Fat Dir Terceiro'!J13 -> UN | H2744: ='Fat Dir Terceiro'!F13 -> 20 | I2744: ='Fat Dir Terceiro'!G13 -> 80 | J2744: ='Fat Dir Terceiro'!M13 -> 3.8.2.002 - Ferramentas manuais | K2744: =INDEX('Curva ABC'!$K$8:$K$2847,MATCH(D2744,'Curva ABC'!$B$8:$B$2847,0)) -> C
... A2787: Fat Dir Terceiro | B2787: ='Fat Dir Terceiro'!A56 -> 0346 | C2787: ='Fat Dir Terceiro'!B56 -> UFV NORONHA VERDE - ESTOQUE MATRIZ FIL 1 | D2787: ='Fat Dir Terceiro'!C56 -> 35313 | E2787: ='Fat Dir Terceiro'!D56 -> 26.13.0053 | F2787: ='Fat Dir Terceiro'!E56 -> PEÇA BORDADA | G2787: ='Fat Dir Terceiro'!J56 -> UN | H2787: ='Fat Dir Terceiro'!F56 -> 3 | I2787: ='Fat Dir Terceiro'!G56 -> 99 | J2787: ='Fat Dir Terceiro'!M56 -> 4.3.4.003 - Fardamentos | K2787: =INDEX('Curva ABC'!$K$8:$K$2847,MATCH(D2787,'Curva ABC'!$B$8:$B$2847,0)) -> C
A2788: Imobilizado | B2788: =Imobilizado!A2 -> 0338 | C2788: =Imobilizado!B2 -> UFV NORONHA VERDE - IMOBILIZADO | D2788: =Imobilizado!C2 -> 18182 | E2788: =Imobilizado!D2 -> 24.25.0003 | F2788: =Imobilizado!E2 -> SERRA CIRCULAR 7.1/4” 1800W 5800RPM CORTE 90GR 62,00MM CORTE 45GR 47,00MM EIXO 5/8” 200V | G2788: =Imobilizado!J2 -> UN | H2788: =Imobilizado!F2 -> 2 | I2788: =Imobilizado!G2 -> 4023.18 | J2788: =Imobilizado!M2 -> 3.8.2.003 - Ferramentas elétricas/pneumáticas | K2788: =INDEX('Curva ABC'!$K$8:$K$2847,MATCH(D2788,'Curva ABC'!$B$8:$B$2847,0)) -> B
A2789: Imobilizado | B2789: =Imobilizado!A3 -> 0338 | C2789: =Imobilizado!B3 -> UFV NORONHA VERDE - IMOBILIZADO | D2789: =Imobilizado!C3 -> 18853 | E2789: =Imobilizado!D3 -> 26.04.0002 | F2789: =Imobilizado!E3 -> CORDA PARA LINHA DE VIDA (TIPO BOMBEIRO/RAPEL) DE POLIAMIDA - TRAÇADO TRIPLO E ALMA CENTRAL C/ ALERT | G2789: =Imobilizado!J3 -> M | H2789: =Imobilizado!F3 -> 150 | I2789: =Imobilizado!G3 -> 602.46 | J2789: =Imobilizado!M3 -> 4.3.4.001 - Equipamento de proteção individual | K2789: =INDEX('Curva ABC'!$K$8:$K$2847,MATCH(D2789,'Curva ABC'!$B$8:$B$2847,0)) -> B
A2790: Imobilizado | B2790: =Imobilizado!A4 -> 0338 | C2790: =Imobilizado!B4 -> UFV NORONHA VERDE - IMOBILIZADO | D2790: =Imobilizado!C4 -> 19215 | E2790: =Imobilizado!D4 -> 29.02.0001 | F2790: =Imobilizado!E4 -> CADEIRA ESCRITÓRIO SECRETÁRIA GIRATÓRIA C/BRAÇO | G2790: =Imobilizado!J4 -> UN | H2790: =Imobilizado!F4 -> 48 | I2790: =Imobilizado!G4 -> 14880 | J2790: =Imobilizado!M4 -> 4.1.1.008 - Mobiliário e acessórios | K2790: =INDEX('Curva ABC'!$K$8:$K$2847,MATCH(D2790,'Curva ABC'!$B$8:$B$2847,0)) -> A
A2791: Imobilizado | B2791: =Imobilizado!A5 -> 0338 | C2791: =Imobilizado!B5 -> UFV NORONHA VERDE - IMOBILIZADO | D2791: =Imobilizado!C5 -> 19240 | E2791: =Imobilizado!D5 -> 29.02.0026 | F2791: =Imobilizado!E5 -> CAMA BELICHE | G2791: =Imobilizado!J5 -> UN | H2791: =Imobilizado!F5 -> 105 | I2791: =Imobilizado!G5 -> 81927.72 | J2791: =Imobilizado!M5 -> 4.1.1.008 - Mobiliário e acessórios | K2791: =INDEX('Curva ABC'!$K$8:$K$2847,MATCH(D2791,'Curva ABC'!$B$8:$B$2847,0)) -> A
A2792: Imobilizado | B2792: =Imobilizado!A6 -> 0338 | C2792: =Imobilizado!B6 -> UFV NORONHA VERDE - IMOBILIZADO | D2792: =Imobilizado!C6 -> 19247 | E2792: =Imobilizado!D6 -> 29.02.0033 | F2792: =Imobilizado!E6 -> ARMÁRIO ROUPEIRO INSALUBRE 2 COLUNAS 4 PORTAS GRANDES PITÃO PARA CADEADO | G2792: =Imobilizado!J6 -> UN | H2792: =Imobilizado!F6 -> 80 | I2792: =Imobilizado!G6 -> 82000 | J2792: =Imobilizado!M6 -> 4.1.1.008 - Mobiliário e acessórios | K2792: =INDEX('Curva ABC'!$K$8:$K$2847,MATCH(D2792,'Curva ABC'!$B$8:$B$2847,0)) -> A
A2793: Imobilizado | B2793: =Imobilizado!A7 -> 0338 | C2793: =Imobilizado!B7 -> UFV NORONHA VERDE - IMOBILIZADO | D2793: =Imobilizado!C7 -> 19255 | E2793: =Imobilizado!D7 -> 29.03.0003 | F2793: =Imobilizado!E7 -> AR CONDICIONADO 12000 BTU/H 220V SPLIT DIGITAL CICLO QUENTE/FRIO | G2793: =Imobilizado!J7 -> UN | H2793: =Imobilizado!F7 -> 14 | I2793: =Imobilizado!G7 -> 28685.02 | J2793: =Imobilizado!M7 -> 4.1.1.009 - Eletro eletrônico e acessórios | K2793: =INDEX('Curva ABC'!$K$8:$K$2847,MATCH(D2793,'Curva ABC'!$B$8:$B$2847,0)) -> A
A2794: Imobilizado | B2794: =Imobilizado!A8 -> 0338 | C2794: =Imobilizado!B8 -> UFV NORONHA VERDE - IMOBILIZADO | D2794: =Imobilizado!C8 -> 19272 | E2794: =Imobilizado!D8 -> 29.03.0020 | F2794: =Imobilizado!E8 -> BEBEDOURO DE COLUNA GELÁGUA | G2794: =Imobilizado!J8 -> UN | H2794: =Imobilizado!F8 -> 3 | I2794: =Imobilizado!G8 -> 2396.4099 | J2794: =Imobilizado!M8 -> 4.1.1.009 - Eletro eletrônico e acessórios | K2794: =INDEX('Curva ABC'!$K$8:$K$2847,MATCH(D2794,'Curva ABC'!$B$8:$B$2847,0)) -> B
A2795: Imobilizado | B2795: =Imobilizado!A9 -> 0338 | C2795: =Imobilizado!B9 -> UFV NORONHA VERDE - IMOBILIZADO | D2795: =Imobilizado!C9 -> 21649 | E2795: =Imobilizado!D9 -> 14.08.0001 | F2795: =Imobilizado!E9 -> TENDA 3,00M X 3,00M | G2795: =Imobilizado!J9 -> UN | H2795: =Imobilizado!F9 -> 17 | I2795: =Imobilizado!G9 -> 40442 | J2795: =Imobilizado!M9 -> 3.8.1.014 - Cobertura | K2795: =INDEX('Curva ABC'!$K$8:$K$2847,MATCH(D2795,'Curva ABC'!$B$8:$B$2847,0)) -> A
A2796: Imobilizado | B2796: =Imobilizado!A10 -> 0338 | C2796: =Imobilizado!B10 -> UFV NORONHA VERDE - IMOBILIZADO | D2796: =Imobilizado!C10 -> 22157 | E2796: =Imobilizado!D10 -> 29.03.0044 | F2796: =Imobilizado!E10 -> AR CONDICIONADO 18000 BTU/H 220V SPLIT | G2796: =Imobilizado!J10 -> UN | H2796: =Imobilizado!F10 -> 44 | I2796: =Imobilizado!G10 -> 127377.68 | J2796: =Imobilizado!M10 -> 4.1.1.009 - Eletro eletrônico e acessórios | K2796: =INDEX('Curva ABC'!$K$8:$K$2847,MATCH(D2796,'Curva ABC'!$B$8:$B$2847,0)) -> A
A2797: Imobilizado | B2797: =Imobilizado!A11 -> 0338 | C2797: =Imobilizado!B11 -> UFV NORONHA VERDE - IMOBILIZADO | D2797: =Imobilizado!C11 -> 22163 | E2797: =Imobilizado!D11 -> 29.03.0045 | F2797: =Imobilizado!E11 -> AR CONDICIONADO 9000 BTU/H 220V SPLIT | G2797: =Imobilizado!J11 -> UN | H2797: =Imobilizado!F11 -> 9 | I2797: =Imobilizado!G11 -> 17043.39 | J2797: =Imobilizado!M11 -> 4.1.1.009 - Eletro eletrônico e acessórios | K2797: =INDEX('Curva ABC'!$K$8:$K$2847,MATCH(D2797,'Curva ABC'!$B$8:$B$2847,0)) -> A
A2798: Imobilizado | B2798: =Imobilizado!A12 -> 0338 | C2798: =Imobilizado!B12 -> UFV NORONHA VERDE - IMOBILIZADO | D2798: =Imobilizado!C12 -> 22239 | E2798: =Imobilizado!D12 -> 24.43.0001 | F2798: =Imobilizado!E12 -> PALETEIRA MANUAL 2.500KG | G2798: =Imobilizado!J12 -> UN | H2798: =Imobilizado!F12 -> 2 | I2798: =Imobilizado!G12 -> 7336.78 | J2798: =Imobilizado!M12 -> 3.8.2.002 - Ferramentas manuais | K2798: =INDEX('Curva ABC'!$K$8:$K$2847,MATCH(D2798,'Curva ABC'!$B$8:$B$2847,0)) -> B
A2799: Imobilizado | B2799: =Imobilizado!A13 -> 0338 | C2799: =Imobilizado!B13 -> UFV NORONHA VERDE - IMOBILIZADO | D2799: =Imobilizado!C13 -> 32009 | E2799: =Imobilizado!D13 -> 29.03.0077 | F2799: =Imobilizado!E13 -> AR CONDICIONADO 9000 BTU/H 220V SPLIT DIGITAL CICLO QUENTE/FRIO' | G2799: =Imobilizado!J13 -> UN | H2799: =Imobilizado!F13 -> 1 | I2799: =Imobilizado!G13 -> 1648.75 | J2799: =Imobilizado!M13 -> 4.1.1.009 - Eletro eletrônico e acessórios | K2799: =INDEX('Curva ABC'!$K$8:$K$2847,MATCH(D2799,'Curva ABC'!$B$8:$B$2847,0)) -> B
... A2878: Imobilizado | B2878: =Imobilizado!A92 -> 0338 | C2878: =Imobilizado!B92 -> UFV NORONHA VERDE - IMOBILIZADO | D2878: =Imobilizado!C92 -> 1475999 | E2878: =Imobilizado!D92 -> 33.01.0079 | F2878: =Imobilizado!E92 -> ROÇADEIRA PODADOR | G2878: =Imobilizado!J92 -> UN | H2878: =Imobilizado!F92 -> 1 | I2878: =Imobilizado!G92 -> 1222.5 | J2878: =Imobilizado!M92 -> 6.1.2.001 - Equipamentos | K2878: =INDEX('Curva ABC'!$K$8:$K$2847,MATCH(D2878,'Curva ABC'!$B$8:$B$2847,0)) -> C

Sheet Uso e Consumo
A1: CODLOC | B1: NOME | C1: IDPRD | D1: CODIGOPRD | E1: NOMEFANTASIA | F1: SALDOFISICO2 | G1: SALDOFINANCEIRO2 | H1: CUSTOMEDIO | I1: CUSTOUNITARIO | J1: CODUNDCONTROLE | K1: FATORCONVERSAO | L1: CODUNDBASE | M1: NATUREZA
A2: 0335 | B2: UFV NORONHA VERDE - USO E CONSUMO | C2: 387747 | D2: 17.01.0846 | E2: CABO DE COBRE NU 50MM²,TÊMPERA MEIO DURA,7 FIOS E ENCORDOAMENTO CLASSE 2A | F2: 8080 | G2: 348968.62 | H2: 43.1892 | I2: 51.1 | J2: M | K2: 1 | L2: M | M2: 3.8.1.017 - Instalações elétricas/telefônicas/lógica
A3: 0335 | B3: UFV NORONHA VERDE - USO E CONSUMO | C3: 1328095 | D3: 17.01.1203 | E3: CABO DE COBRE MONOPOLAR 240 MM², CLASSE 2, 8,7/15 KV, ISOLAÇÃO EPR, COBERTURA PVC PRETO, BLINDAGEM 25 MM² | F3: 1000 | G3: 340633.99 | H3: 340.634 | I3: 340.6528 | J3: M | K3: 1 | L3: M | M3: 3.8.1.017 - Instalações elétricas/telefônicas/lógica
A4: 0335 | B4: UFV NORONHA VERDE - USO E CONSUMO | C4: 1092910 | D4: 02.01.0080 | E4: TELA DO TIPO ALAMBRADO, MALHA DE ARAME EM AÇO GALVANIZADO. BWG 12 E ABERTURA DE 50MM (9,70M² POR PORTÃO) | F4: 13307.4 | G4: 319377.6 | H4: 24 | I4: 24 | J4: M2 | K4: 1 | L4: M2 | M4: 3.8.1.002 - Telas e arames
A5: 0335 | B5: UFV NORONHA VERDE - USO E CONSUMO | C5: 1485414 | D5: 17.24.0018 | E5: CAIXA DE INTERLIGAÇÃO EM AÇO INOX 304 PARA TP | F5: 13 | G5: 198764.12 | H5: 15289.548 | I5: 15359.603 | J5: UN | K5: 1 | L5: UN | M5: 3.8.1.017 - Instalações elétricas/telefônicas/lógica
A6: 0335 | B6: UFV NORONHA VERDE - USO E CONSUMO | C6: 1321831 | D6: 17.08.0218 | E6: QUADRO DE DISTRIBUIÇÃO DE CORRENTE CONTÍNUA, 2 ENTRADAS DE TENSÃO 125Vcc - 300A - 10kA | F6: 2 | G6: 171047.93 | H6: 85523.965 | I6: 85523.97 | J6: UN | K6: 1 | L6: UN | M6: 3.8.1.017 - Instalações elétricas/telefônicas/lógica
A7: 0335 | B7: UFV NORONHA VERDE - USO E CONSUMO | C7: 1321832 | D7: 17.08.0219 | E7: QUADRO DE DISTRIBUIÇÃO DE CORRENTE ALTERNADA, 2 ENTRADAS DE TENSÃO 380/220Vca - 300A - 10kA | F7: 2 | G7: 169258.31 | H7: 84629.155 | I7: 84629.15 | J7: UN | K7: 1 | L7: UN | M7: 3.8.1.017 - Instalações elétricas/telefônicas/lógica
A8: 0335 | B8: UFV NORONHA VERDE - USO E CONSUMO | C8: 57985 | D8: 09.19.0032 | E8: PISO INTERTRAVADO CONCRETO RETANGULAR 10,00CM X 20,00CM X 8,00CM NATURAL | F8: 2587.5 | G8: 163012.5 | H8: 63 | I8: 63 | J8: M2 | K8: 1 | L8: M2 | M8: 3.8.1.010 - Revestimentos e pisos
A9: 0335 | B9: UFV NORONHA VERDE - USO E CONSUMO | C9: 742688 | D9: 09.16.0030 | E9: MOURÃO DE CONCRETO 10 X 10 CM NOS VÉRTICES, E A CADA 100 M | F9: 2100 | G9: 159390 | H9: 75.9 | I9: 75.9 | J9: UN | K9: 1 | L9: UN | M9: 3.8.1.009 - Artefatos pré-moldados de concreto
A10: 0335 | B10: UFV NORONHA VERDE - USO E CONSUMO | C10: 1322477 | D10: 17.01.1198 | E10: CABO UNIPOLAR DE COBRE, CLASSE 8,7/15KV, ISOL. HEPR, COB. PVC SEÇÃO 150MM², BLINDAGEM 25MM². REF PRYSMIAN OU SIMILAR | F10: 804 | G10: 151354.5 | H10: 188.2519 | I10: 188.245 | J10: M | K10: 1 | L10: M | M10: 3.8.1.017 - Instalações elétricas/telefônicas/lógica
A11: 0335 | B11: UFV NORONHA VERDE - USO E CONSUMO | C11: 884974 | D11: 17.22.0110 | E11: ALÇA PREFORMADA PARA AMARRAÇÃO DO CABO NU | F11: 600 | G11: 142639.77 | H11: 237.733 | I11: 404.22 | J11: UND | K11: 1 | L11: UND | M11: 3.8.1.017 - Instalações elétricas/telefônicas/lógica
A12: 0335 | B12: UFV NORONHA VERDE - USO E CONSUMO | C12: 1328795 | D12: 32.07.0231 | E12: RETIFICADOR 380VCA 3F - 125 VCC / 48 VCC / 12 VCC CHAVEADO EM ALTA FREQUÊNCIA 11,11 KVA | F12: 2 | G12: 137108.08 | H12: 68554.04 | I12: 68554.04 | J12: UN | K12: 1 | L12: UN | M12: 6.1.2.001 - Equipamentos
A13: 0335 | B13: UFV NORONHA VERDE - USO E CONSUMO | C13: 53717 | D13: 18.07.0053 | E13: CAIXA D´AGUA POLIETILENO 10.000L C/ TAMPA | F13: 10 | G13: 119800 | H13: 11980 | I13: 11980 | J13: UN | K13: 1 | L13: UN | M13: 3.8.1.018 - Instalações hidráulicas/sanitárias/industriais
... A2732: 0335 | B2732: UFV NORONHA VERDE - USO E CONSUMO | C2732: 1614274 | D2732: 17.03.0621 | E2732: BUCHA EXPANSAO NYLON N8 40MM | F2732: 6 | G2732: 0.48 | H2732: 0.08 | I2732: 0.08 | J2732: UN | K2732: 1 | L2732: UN | M2732: 3.8.1.017 - Instalações elétricas/telefônicas/lógica
F2733: TOTAL | G2733: =SUM(G2:G2732) -> 10186546

Sheet Fat Dir Terceiro
A1: CODLOC | B1: NOME | C1: IDPRD | D1: CODIGOPRD | E1: NOMEFANTASIA | F1: SALDOFISICO2 | G1: SALDOFINANCEIRO2 | H1: CUSTOMEDIO | I1: CUSTOUNITARIO | J1: CODUNDCONTROLE | K1: FATORCONVERSAO | L1: CODUNDBASE | M1: NATUREZA
A2: 0336 | B2: UFV NORONHA VERDE - FAT. DIR. TERCEIRO | C2: 17864 | D2: 24.04.0007 | E2: PRUMO PAREDE AÇO SAE 1020 CORDAO NYLON TAÇO MADEIRA 400,00G | F2: 10 | G2: 340 | H2: 34 | I2: 34 | J2: UN | K2: 1 | L2: UN | M2: 3.8.2.001 - Ferramentas medição/aferição
A3: 0336 | B3: UFV NORONHA VERDE - FAT. DIR. TERCEIRO | C3: 17885 | D3: 24.07.0002 | E3: TRENA CURTA 8,00M CAIXA FECHADA PLASTICA FITA AÇO TEMPERADO | F3: 12 | G3: 528 | H3: 44 | I3: 44 | J3: UN | K3: 1 | L3: UN | M3: 3.8.2.001 - Ferramentas medição/aferição
A4: 0336 | B4: UFV NORONHA VERDE - FAT. DIR. TERCEIRO | C4: 18164 | D4: 24.21.0001 | E4: SERROTE PROFISSIONAL 18" CORPO AÇO CARBONO CABO MADEIRA 9 DENTES P/POLEGADA | F4: 8 | G4: 264 | H4: 33 | I4: 33 | J4: UN | K4: 1 | L4: UN | M4: 3.8.2.002 - Ferramentas manuais
A5: 0336 | B5: UFV NORONHA VERDE - FAT. DIR. TERCEIRO | C5: 21111 | D5: 30.02.0043 | E5: LIMPA CONTATO ELÉTRICO/ELETÔNICO 300ML | F5: 12 | G5: 194.52 | H5: 16.21 | I5: 16.21 | J5: UN | K5: 1 | L5: UN | M5: 4.1.1.002 - Material expediente
A6: 0336 | B6: UFV NORONHA VERDE - FAT. DIR. TERCEIRO | C6: 21297 | D6: 24.28.0001 | E6: LÁPIS PARA CARPINTEIRO | F6: 50 | G6: 87.5 | H6: 1.75 | I6: 1.75 | J6: UN | K6: 1 | L6: UN | M6: 3.8.2.002 - Ferramentas manuais
A7: 0336 | B7: UFV NORONHA VERDE - FAT. DIR. TERCEIRO | C7: 21488 | D7: 16.05.0076 | E7: TRINCHA 4" N500 CABO DE PVC | F7: 10 | G7: 115 | H7: 11.5 | I7: 11.5 | J7: UN | K7: 1 | L7: UN | M7: 3.8.1.016 - Pinturas
A8: 0336 | B8: UFV NORONHA VERDE - FAT. DIR. TERCEIRO | C8: 22252 | D8: 25.10.0021 | E8: LINHA NYLON P/ PEDREIRO 1,0MM X 100M | F8: 40 | G8: 680 | H8: 17 | I8: 17 | J8: UN | K8: 1 | L8: UN | M8: 3.8.2.006 - Utensílios
A9: 0336 | B9: UFV NORONHA VERDE - FAT. DIR. TERCEIRO | C9: 22375 | D9: 25.20.0001 | E9: ARCO DE SERRA FIXO 12 POL REF.STARRET-140 | F9: 10 | G9: 548 | H9: 54.8 | I9: 54.8 | J9: UN | K9: 1 | L9: UN | M9: 3.8.2.006 - Utensílios
A10: 0336 | B10: UFV NORONHA VERDE - FAT. DIR. TERCEIRO | C10: 23269 | D10: 16.05.0081 | E10: TRINCHA 1.1/2 | F10: 10 | G10: 38 | H10: 3.8 | I10: 3.8 | J10: UN | K10: 1 | L10: UN | M10: 3.8.1.016 - Pinturas
A11: 0336 | B11: UFV NORONHA VERDE - FAT. DIR. TERCEIRO | C11: 23796 | D11: 25.03.0171 | E11: BROCA CONCRETO 8MM | F11: 12 | G11: 81.24 | H11: 6.77 | I11: 6.77 | J11: UN | K11: 1 | L11: UN | M11: 3.8.2.004 - Consumíveis para corte, perfuração e desbaste
A12: 0336 | B12: UFV NORONHA VERDE - FAT. DIR. TERCEIRO | C12: 24365 | D12: 25.03.0178 | E12: BROCA CONCRETO 12MM | F12: 24 | G12: 287.28 | H12: 11.97 | I12: 11.97 | J12: UN | K12: 1 | L12: UN | M12: 3.8.2.004 - Consumíveis para corte, perfuração e desbaste
A13: 0336 | B13: UFV NORONHA VERDE - FAT. DIR. TERCEIRO | C13: 54662 | D13: 24.33.0003 | E13: BLOCO DE ESPUMA 12,00 CM X 6,00 CM X 22,00 CM | F13: 20 | G13: 80 | H13: 4 | I13: 4 | J13: UN | K13: 1 | L13: UN | M13: 3.8.2.002 - Ferramentas manuais
... A56: 0346 | B56: UFV NORONHA VERDE - ESTOQUE MATRIZ FIL 1 | C56: 35313 | D56: 26.13.0053 | E56: PEÇA BORDADA | F56: 3 | G56: 99 | H56: 33 | I56: 33 | J56: UN | K56: 1 | L56: UN | M56: 4.3.4.003 - Fardamentos
F57: TOTAL | G57: =SUM(G2:G56) -> 2934269.7

Sheet Imobilizado
A1: CODLOC | B1: NOME | C1: IDPRD | D1: CODIGOPRD | E1: NOMEFANTASIA | F1: SALDOFISICO2 | G1: SALDOFINANCEIRO2 | H1: CUSTOMEDIO | I1: CUSTOUNITARIO | J1: CODUNDCONTROLE | K1: FATORCONVERSAO | L1: CODUNDBASE | M1: NATUREZA
A2: 0338 | B2: UFV NORONHA VERDE - IMOBILIZADO | C2: 18182 | D2: 24.25.0003 | E2: SERRA CIRCULAR 7.1/4” 1800W 5800RPM CORTE 90GR 62,00MM CORTE 45GR 47,00MM EIXO 5/8” 200V | F2: 2 | G2: 4023.18 | H2: 2011.59 | I2: 2011.59 | J2: UN | K2: 1 | L2: UN | M2: 3.8.2.003 - Ferramentas elétricas/pneumáticas
A3: 0338 | B3: UFV NORONHA VERDE - IMOBILIZADO | C3: 18853 | D3: 26.04.0002 | E3: CORDA PARA LINHA DE VIDA (TIPO BOMBEIRO/RAPEL) DE POLIAMIDA - TRAÇADO TRIPLO E ALMA CENTRAL C/ ALERT | F3: 150 | G3: 602.46 | H3: 4.0164 | I3: 4.0164 | J3: M | K3: 1 | L3: M | M3: 4.3.4.001 - Equipamento de proteção individual
A4: 0338 | B4: UFV NORONHA VERDE - IMOBILIZADO | C4: 19215 | D4: 29.02.0001 | E4: CADEIRA ESCRITÓRIO SECRETÁRIA GIRATÓRIA C/BRAÇO | F4: 48 | G4: 14880 | H4: 310 | I4: 310 | J4: UN | K4: 1 | L4: UN | M4: 4.1.1.008 - Mobiliário e acessórios
A5: 0338 | B5: UFV NORONHA VERDE - IMOBILIZADO | C5: 19240 | D5: 29.02.0026 | E5: CAMA BELICHE | F5: 105 | G5: 81927.72 | H5: 780.264 | I5: 780.264 | J5: UN | K5: 1 | L5: UN | M5: 4.1.1.008 - Mobiliário e acessórios
A6: 0338 | B6: UFV NORONHA VERDE - IMOBILIZADO | C6: 19247 | D6: 29.02.0033 | E6: ARMÁRIO ROUPEIRO INSALUBRE 2 COLUNAS 4 PORTAS GRANDES PITÃO PARA CADEADO | F6: 80 | G6: 82000 | H6: 1025 | I6: 1025 | J6: UN | K6: 1 | L6: UN | M6: 4.1.1.008 - Mobiliário e acessórios
A7: 0338 | B7: UFV NORONHA VERDE - IMOBILIZADO | C7: 19255 | D7: 29.03.0003 | E7: AR CONDICIONADO 12000 BTU/H 220V SPLIT DIGITAL CICLO QUENTE/FRIO | F7: 14 | G7: 28685.02 | H7: 2048.93 | I7: 2048.93 | J7: UN | K7: 1 | L7: UN | M7: 4.1.1.009 - Eletro eletrônico e acessórios
A8: 0338 | B8: UFV NORONHA VERDE - IMOBILIZADO | C8: 19272 | D8: 29.03.0020 | E8: BEBEDOURO DE COLUNA GELÁGUA | F8: 3 | G8: 2396.4099 | H8: 798.8033 | I8: 798.8033 | J8: UN | K8: 1 | L8: UN | M8: 4.1.1.009 - Eletro eletrônico e acessórios
A9: 0338 | B9: UFV NORONHA VERDE - IMOBILIZADO | C9: 21649 | D9: 14.08.0001 | E9: TENDA 3,00M X 3,00M | F9: 17 | G9: 40442 | H9: 2378.9412 | I9: 2378.9412 | J9: UN | K9: 1 | L9: UN | M9: 3.8.1.014 - Cobertura
A10: 0338 | B10: UFV NORONHA VERDE - IMOBILIZADO | C10: 22157 | D10: 29.03.0044 | E10: AR CONDICIONADO 18000 BTU/H 220V SPLIT | F10: 44 | G10: 127377.68 | H10: 2894.9473 | I10: 2894.9473 | J10: UN | K10: 1 | L10: UN | M10: 4.1.1.009 - Eletro eletrônico e acessórios
A11: 0338 | B11: UFV NORONHA VERDE - IMOBILIZADO | C11: 22163 | D11: 29.03.0045 | E11: AR CONDICIONADO 9000 BTU/H 220V SPLIT | F11: 9 | G11: 17043.39 | H11: 1893.71 | I11: 1893.71 | J11: UN | K11: 1 | L11: UN | M11: 4.1.1.009 - Eletro eletrônico e acessórios
A12: 0338 | B12: UFV NORONHA VERDE - IMOBILIZADO | C12: 22239 | D12: 24.43.0001 | E12: PALETEIRA MANUAL 2.500KG | F12: 2 | G12: 7336.78 | H12: 3668.39 | I12: 3668.39 | J12: UN | K12: 1 | L12: UN | M12: 3.8.2.002 - Ferramentas manuais
A13: 0338 | B13: UFV NORONHA VERDE - IMOBILIZADO | C13: 32009 | D13: 29.03.0077 | E13: AR CONDICIONADO 9000 BTU/H 220V SPLIT DIGITAL CICLO QUENTE/FRIO' | F13: 1 | G13: 1648.75 | H13: 1648.75 | I13: 1648.75 | J13: UN | K13: 1 | L13: UN | M13: 4.1.1.009 - Eletro eletrônico e acessórios
... A92: 0338 | B92: UFV NORONHA VERDE - IMOBILIZADO | C92: 1475999 | D92: 33.01.0079 | E92: ROÇADEIRA PODADOR | F92: 1 | G92: 1222.5 | H92: 1222.5 | I92: 1222.5 | J92: UN | K92: 1 | L92: UN | M92: 6.1.2.001 - Equipamentos
F93: TOTAL | G93: =SUM(G2:G92) -> 2117923.5
